# ИСКЛЮЧЕНИЯ И ОШИБКИ
Вопросы:
- [1. Что для программы является исключительной ситуацией? Какие существуют способы обработки ошибок в программах?](#что-для-программы-является-исключительной-ситуацией-какие-существуют-способы-обработки-ошибок-в-программах)
- [2. Что такое исключение для Java-программы? Что значит «программа генерировала\выбросила исключение»? Привести пример, когда исключения генерируются виртуальной машиной (автоматически) и когда необходимо их генерировать вручную.](#что-такое-исключение-для-java-программы-что-значит-программа-генерировалавыбросила-исключение-привести-пример-когда-исключения-генерируются-виртуальной-машиной-автоматически-и-когда-необходимо-их-генерировать-вручную)
- [3. Привести иерархию классов-исключений, делящую исключения на проверяемые и непроверяемые. В чем особенности проверяемых и непроверяемых исключений?](#привести-иерархию-классов-исключений-делящую-исключения-на-проверяемые-и-непроверяемые-в-чем-особенности-проверяемых-и-непроверяемых-исключений)
- [4. Объяснить работу оператора try-catch-finally. Когда данный оператор следует использовать? Сколько блоков catch может соответствовать одному блоку try?](#объяснить-работу-оператора-try-catch-finally-когда-данный-оператор-следует-использовать-сколько-блоков-catch-может-соответствовать-одному-блоку-try)
- [5. Можно ли вкладывать блоки try друг в друга, можно ли вложить блок try в catch или finally? Как происходит обработка исключений, выброшенных внутренним блоком try, если среди его блоков catch нет подходящего?](#можно-ли-вкладывать-блоки-try-друг-в-друга-можно-ли-вложить-блок-try-в-catch-или-finally-как-происходит-обработка-исключений-выброшенных-внутренним-блоком-try-если-среди-его-блоков-catch-нет-подходящего)
- [6. Что называют стеком операторов try? Как работает блок try с ресурсами?](#что-называют-стеком-операторов-try-как-работает-блок-try-с-ресурсами)
- [7. Указать правило расположения блоков catch в зависимости от типов перехватываемых исключений. Может ли перехваченное исключение быть сгенерировано снова, и, если да, то как и кто в этом случае будет обрабатывать повторно сгенерированное исключение? Может ли блок catch выбрасывать иные исключения, и если да, то привести пример, когда это может быть необходимо.](#указать-правило-расположения-блоков-catch-в-зависимости-от-типов-перехватываемых-исключений-может-ли-перехваченное-исключение-быть-сгенерировано-снова-и-если-да-то-как-и-кто-в-этом-случае-будет-обрабатывать-повторно-сгенерированное-исключение-может-ли-блок-catch-выбрасывать-иные-исключения-и-если-да-то-привести-пример-когда-это-может-быть-необходимо)
- [8. Когда происходит вызов блока finally? Существуют ли ситуации, когда блок finally не будет вызван? Может ли блок finally выбрасывать исключения? Может ли блок finally выполниться дважды?](#когда-происходит-вызов-блока-finally-существуют-ли-ситуации-когда-блок-finally-не-будет-вызван-может-ли-блок-finally-выбрасывать-исключения-может-ли-блок-finally-выполниться-дважды)
- [9. Как генерировать исключение вручную? Объекты каких классов могут быть генерированы в качестве исключений? Можно ли генерировать два исключения одновременно?](#как-генерировать-исключение-вручную-объекты-каких-классов-могут-быть-генерированы-в-качестве-исключений-можно-ли-генерировать-два-исключения-одновременно)
- [10. Объяснить, как работают операторы throw и throws. В чем их отличия?](#объяснить-как-работают-операторы-throw-и-throws-в-чем-их-отличия)
- [11. Объяснить правила реализации секции throws при переопределении метода и при описании конструкторов производного класса.](#объяснить-правила-реализации-секции-throws-при-переопределении-метода-и-при-описании-конструкторов-производного-класса)
- [12. Как ведет себя блок throws при работе с проверяемыми и непроверяемыми исключениями?](#как-ведет-себя-блок-throws-при-работе-с-проверяемыми-и-непроверяемыми-исключениями)
- [13. Каков будет результат создания объекта, если конструктор при работе сгенерирует исключительную ситуацию?](#каков-будет-результат-создания-объекта-если-конструктор-при-работе-сгенерирует-исключительную-ситуацию)
- [14. Нужно ли генерировать исключения, входящие в Java SE? Как создать собственные классы исключений?](#нужно-ли-генерировать-исключения-входящие-в-java-se-как-создать-собственные-классы-исключений)

## Что для программы является исключительной ситуацией? Какие существуют способы обработки ошибок в программах?
Исключительная ситуация (или исключение) - это непредвиденное событие, которое возникает во время выполнения программы и прерывает ее нормальный поток выполнения. Это может быть вызвано ошибкой ввода-вывода, делением на ноль, отсутствием ресурсов, выходом за пределы массива и т. д.

В Java исключения представлены объектами классов, наследующихся от `Throwable`. Когда возникает исключение, создается объект этого класса и передается обработчику (пользовательскому коду) для обработки.

Существуют различные способы обработки ошибок в программах:

1. Использование блоков try-catch: При помощи конструкции try-catch можно обработать исключение, предотвратив прерывание выполнения программы. В блоке `try` помещается код, который может вызвать исключение, а в блоке `catch` - код для обработки исключения.

```java
try {
    // Код, который может вызвать исключение
} catch (ExceptionType e) {
    // Код для обработки исключения
}
```

2. Использование блока finally: Блок `finally` позволяет выполнить код независимо от того, возникло исключение или нет. Этот блок выполняется всегда, даже если исключение было перехвачено и обработано.

```java
try {
    // Код, который может вызвать исключение
} catch (ExceptionType e) {
    // Код для обработки исключения
} finally {
    // Код, который всегда будет выполнен
}
```

3. Использование множественных блоков catch: Можно использовать несколько блоков catch для обработки разных типов исключений.

```java
try {
    // Код, который может вызвать исключение
} catch (Type1Exception e) {
    // Код для обработки исключения типа Type1Exception
} catch (Type2Exception e) {
    // Код для обработки исключения типа Type2Exception
}
```

4. Использование throws: Ключевое слово `throws` используется в объявлении метода для указания, что этот метод может выбрасывать определенное исключение, которое должно быть обработано вызывающим кодом.

```java
public void someMethod() throws SomeException {
    // Код, который может выбросить SomeException
}
```

5. Создание пользовательских исключений: В Java можно создавать собственные пользовательские исключения, расширяя классы `Exception` или `RuntimeException`. Это позволяет определить свои собственные типы исключений, которые отражают специфические ситуации в программе.

```java
public class CustomException extends Exception {
    // Код для пользовательского исключения
}
```

Правильная обработка исключений позволяет сделать программы более надежными и устойчивыми к ошибкам, а также облегчает отладку и обнаружение проблем.

[к оглавлению](#исключения-и-ошибки)

## Что такое исключение для Java-программы? Что значит «программа генерировала\выбросила исключение»? Привести пример, когда исключения генерируются виртуальной машиной (автоматически) и когда необходимо их генерировать вручную.
Исключение 
Java - это объект, который представляет собой непредвиденную ситуацию, возникающую во время выполнения программы и прерывающую ее нормальное выполнение. Когда программа сталкивается с ошибкой или иной исключительной ситуацией, она "генерирует" или "выбрасывает" исключение. Это означает, что программа создает объект исключения и передает его обработчику, который будет заниматься его обработкой.

Исключения могут возникать автоматически, когда виртуальная машина обнаруживает ошибку в ходе выполнения программы. Например:

1. Попытка деления на ноль:
```java
int a = 10;
int b = 0;
int result = a / b; // Здесь возникнет исключение ArithmeticException
```

2. Обращение к элементу массива с недопустимым индексом:
```java
int[] array = {1, 2, 3};
int element = array[5]; // Здесь возникнет исключение ArrayIndexOutOfBoundsException
```

3. Ошибка чтения файла:
```java
try {
    BufferedReader reader = new BufferedReader(new FileReader("file.txt"));
    String line = reader.readLine(); // Здесь возможно исключение IOException
    // Код для обработки строки из файла
} catch (IOException e) {
    // Обработка исключения
}
```

Исключения также могут быть сгенерированы вручную, когда разработчик программы хочет явно указать на ошибочное состояние или специфическую ситуацию. Это делается путем создания объекта исключения и его выбрасывания с помощью ключевого слова `throw`. Пример:

```java
public void someMethod(int value) throws CustomException {
    if (value < 0) {
        throw new CustomException("Значение не может быть отрицательным");
    }
    // Код метода
}
```

Здесь `CustomException` - это пользовательское исключение, которое было определено программистом для обозначения ситуации, когда значение аргумента должно быть положительным.

Генерирование и обработка исключений является важной частью разработки программ, так как позволяет более понятно и четко обрабатывать ошибки и особые ситуации, а также улучшить общую надежность и стабильность программы.
[к оглавлению](#исключения-и-ошибки)

## Привести иерархию классов-исключений, делящую исключения на проверяемые и непроверяемые. В чем особенности проверяемых и непроверяемых исключений?
Иерархия классов-исключений в Java делит исключения на две категории: проверяемые (checked) и непроверяемые (unchecked).

1. Проверяемые исключения (Checked Exceptions):
   Проверяемые исключения представляют собой такие исключения, которые должны быть обрабатываны программистом явно, чтобы предотвратить возникновение ошибок во время выполнения программы. Все проверяемые исключения являются подклассами класса `java.lang.Exception`, за исключением класса `java.lang.RuntimeException` и его подклассов.

Примеры проверяемых исключений:
- `IOException` (например, при работе с файлами и потоками ввода-вывода).
- `SQLException` (исключения, связанные с работой с базами данных).
- `ClassNotFoundException` (если класс не может быть найден во время выполнения программы).

Ключевая особенность проверяемых исключений - обязательное обработка (или объявление их в сигнатуре метода с помощью `throws`) в тех методах, которые могут вызывать эти исключения. Это помогает обеспечить более безопасное и надежное выполнение программы.

2. Непроверяемые исключения (Unchecked Exceptions):
   Непроверяемые исключения (также называемые неотслеживаемыми или runtime-исключениями) - это исключения, которые не требуют явного обработки или объявления в сигнатуре метода. Они являются подклассами класса `java.lang.RuntimeException` и его подклассов.

Примеры непроверяемых исключений:
- `ArithmeticException` (возникает при делении на ноль или других арифметических ошибках).
- `NullPointerException` (когда программа обращается к объекту, у которого значение `null`).
- `ArrayIndexOutOfBoundsException` (если индекс массива находится за пределами его допустимого диапазона).

Ключевая особенность непроверяемых исключений - программист может выбрать, обрабатывать их или нет, поскольку они возникают из-за ошибок в логике программы, которые могут быть предотвращены путем проверок в коде.

Общая иерархия исключений:
```
Throwable
    ├── Error
    └── Exception
          ├── RuntimeException (непроверяемые исключения)
          └── IOException и другие (проверяемые исключения)
```

Важно понимать различие между проверяемыми и непроверяемыми исключениями, чтобы эффективно их обрабатывать и предотвращать возможные ошибки в программе.

[к оглавлению](#исключения-и-ошибки)

## Объяснить работу оператора try-catch-finally. Когда данный оператор следует использовать? Сколько блоков catch может соответствовать одному блоку try?
Оператор try-catch-finally предназначен для обработки исключений в Java. Он позволяет поймать и обработать исключение, которое может возникнуть в блоке кода (try-блоке), и выполнить определенные действия независимо от того, возникло исключение или нет (блок finally).

Работа оператора try-catch-finally:

1. `try`: Внутри блока try помещается код, который потенциально может вызвать исключение. Если во время выполнения кода внутри блока try возникает исключение, то выполнение кода внутри try-блока прекращается.

2. `catch`: Если в блоке try возникло исключение, то управление передается в соответствующий блок catch, который обрабатывает это исключение. В блоке catch указывается тип исключения, который должен быть обработан. Если тип исключения совпадает с типом, выброшенным в блоке try, то код внутри соответствующего блока catch выполняется.

3. `finally`: Блок finally следует после блока try-catch и содержит код, который будет выполнен независимо от того, возникло исключение или нет в блоке try. Блок finally полезен для выполнения завершающих действий, таких как закрытие ресурсов (например, файлов или сетевых подключений), которые должны быть выполнены независимо от успешного выполнения кода в try-блоке или возникновения исключений.

Когда следует использовать оператор try-catch-finally?

Оператор try-catch-finally следует использовать в тех случаях, когда в коде может возникнуть исключение, и нужно предоставить обработку этого исключения. Такой подход позволяет более контролируемо и надежно управлять ошибками, предотвращая неконтролируемое завершение программы.

Сколько блоков catch может соответствовать одному блоку try?

В одном операторе try может быть несколько блоков catch, и каждый блок catch обрабатывает свой тип исключения. Это позволяет обработать различные типы исключений разными способами в одной конструкции try-catch. Блоки catch следуют непосредственно друг за другом, и выполнение передается в первый подходящий по типу блок catch.

[к оглавлению](#исключения-и-ошибки)

## Можно ли вкладывать блоки try друг в друга, можно ли вложить блок try в catch или finally? Как происходит обработка исключений, выброшенных внутренним блоком try, если среди его блоков catch нет подходящего?
Да, блоки try можно вкладывать друг в друга. Это называется вложенными блоками try-catch.

Также, можно вложить блок try в блок catch или finally. Это позволяет дополнительно обрабатывать исключения, которые могут возникнуть внутри других блоков обработки исключений или в блоках, где выполняются завершающие действия (блок finally).

Процесс обработки исключений во вложенных блоках try-catch следующий:

1. Если внутренний блок try генерирует исключение, то происходит поиск соответствующего блока catch внутри этого блока try. Если такой блок catch найден, то он обрабатывает исключение.

2. Если внутренний блок try не содержит подходящего блока catch, то исключение передается на уровень выше, во внешний блок try-catch (если он есть). Происходит поиск соответствующего блока catch на уровне выше. Если такой блок catch найден, то он обрабатывает исключение.

3. Процесс поиска блока catch продолжается до тех пор, пока не будет найден соответствующий блок catch или до достижения главного метода (main) программы. Если на всех уровнях не будет найден подходящий блок catch, программа завершится аварийно с сообщением об ошибке.

При использовании вложенных блоков try-catch следует быть внимательным, чтобы не возникло неявного подавления ошибок. Это может привести к тому, что исключение будет перехвачено внутри вложенного блока try и не будет обработано на более высоком уровне, где это было бы корректным. Поэтому следует внимательно планировать структуру блоков try-catch в программе и обеспечить корректное и своевременное обработку исключений.

[к оглавлению](#исключения-и-ошибки)

## Что называют стеком операторов try? Как работает блок try с ресурсами?
Стек операторов try (try-with-resources) - это конструкция в Java, которая предназначена для автоматического закрытия ресурсов после окончания их использования, даже в случае возникновения исключения.

Конструкция try-with-resources представляет собой следующую форму:

```java
try (ресурс1, ресурс2, ..., ресурсN) {
    // код, использующий ресурсы
} catch (Исключение e) {
    // обработка исключения (опционально)
}
```

В блоке try с ресурсами ресурсы объявляются и инициализируются в скобках после ключевого слова `try`. Эти ресурсы должны реализовывать интерфейс `java.lang.AutoCloseable` или `java.io.Closeable`. После выполнения блока try (независимо от того, завершился он успешно или было выброшено исключение), ресурсы автоматически закрываются методом `close()`.

Если в блоке try происходит исключение, то в первую очередь вызывается метод `close()` для каждого ресурса, а затем исключение передается на обработку в блок catch.

Таким образом, блок try с ресурсами гарантирует, что ресурсы будут закрыты надлежащим образом, даже в случае возникновения исключения. Это упрощает и обезопасивает работу с ресурсами, такими как файлы, сокеты и другие, которые нужно корректно закрывать после использования.

[к оглавлению](#исключения-и-ошибки)

## Указать правило расположения блоков catch в зависимости от типов перехватываемых исключений. Может ли перехваченное исключение быть сгенерировано снова, и, если да, то как и кто в этом случае будет обрабатывать повторно сгенерированное исключение? Может ли блок catch выбрасывать иные исключения, и если да, то привести пример, когда это может быть необходимо.
При использовании нескольких блоков catch в операторе try-catch, блоки должны быть расположены таким образом, чтобы более специфичные типы исключений идут перед более общими типами. Такой порядок важен, потому что при возникновении исключения, Java будет искать соответствующий блок catch сверху вниз и будет использовать первый подходящий блок catch для обработки исключения. Если более общий тип исключения расположен перед более специфичным, то более специфичный блок catch никогда не будет выполнен.

Например:

```java
try {
    // Код, который может вызывать исключения
} catch (IOException e) {
    // Обработка IOException
} catch (FileNotFoundException e) {
    // Обработка FileNotFoundException
} catch (Exception e) {
    // Обработка всех остальных исключений
}
```

В данном примере, если возникнет `FileNotFoundException`, то будет обработан первый блок catch, и более общий блок catch `Exception` не будет выполнен.

Перехваченное исключение может быть сгенерировано снова с помощью оператора `throw`. Это может быть полезно, если нужно дополнительно обработать исключение в блоке catch и потом передать его дальше для обработки другим частям программы или методам.

Пример:

```java
try {
    // Код, который может вызывать исключения
} catch (IOException e) {
    // Обработка IOException
    throw e; // Повторное выбрасывание IOException
}
```

В этом примере, исключение `IOException` перехватывается в блоке catch, затем обрабатывается, и после этого выбрасывается снова, чтобы его могли обработать другие части программы или методы.

Блок catch также может выбрасывать иные исключения, используя оператор `throw`. Это может быть полезно, если нужно преобразовать одно исключение в другое, чтобы более точно передать информацию об ошибке или чтобы выполнить специфическую обработку.

Пример:

```java
try {
    // Код, который может вызывать исключения
} catch (IOException e) {
    // Обработка IOException
    throw new CustomException("Something went wrong", e); // Выбрасывание CustomException
}
```

В этом примере, блок catch для `IOException` выбрасывает новое исключение `CustomException`, которое содержит дополнительную информацию об ошибке и оборачивает исходное исключение `IOException` как причину.

[к оглавлению](#исключения-и-ошибки)

## Когда происходит вызов блока finally? Существуют ли ситуации, когда блок finally не будет вызван? Может ли блок finally выбрасывать исключения? Может ли блок finally выполниться дважды?
Блок `finally` выполняется всегда независимо от того, было ли выброшено исключение или нет. Он используется для выполнения кода, который должен быть гарантированно выполнен вне зависимости от того, произошла ошибка или нет.

Есть несколько ситуаций, когда блок `finally` не будет вызван:

1. Если в блоке `try` произошло фатальное исключение, которое прерывает работу программы, например, `OutOfMemoryError`, `StackOverflowError` и т.д. В таком случае, блок `finally` не будет выполнен, так как выполнение программы завершится.

2. Если JVM был принудительно остановлен, например, с помощью `System.exit()`, то блок `finally` не будет вызван.

Блок `finally` может выбрасывать исключения, и если это произойдет, то любое исключение, выброшенное в блоке `finally`, заменит любое исключение, которое было выброшено ранее в блоке `try` или в блоке `catch`. Если блок `finally` выбрасывает исключение, то это исключение будет передано выше, и если в методе, содержащем блок `try`, нет блока `catch`, чтобы его обработать, то это исключение может быть перехвачено в вызывающем коде.

Блок `finally` не выполнится дважды в нормальных обстоятельствах. Он будет выполнен ровно один раз после выполнения блока `try`, независимо от того, было ли выброшено исключение или нет. Однако, есть несколько специфических случаев, например, при использовании рекурсии и вызове блока `finally` из другого блока `finally`, когда возможны неожиданные поведения, и блок `finally` может быть выполнен несколько раз, что может привести к проблемам и ошибкам в программе.

[к оглавлению](#исключения-и-ошибки)

## Как генерировать исключение вручную? Объекты каких классов могут быть генерированы в качестве исключений? Можно ли генерировать два исключения одновременно?
Для того чтобы сгенерировать исключение вручную, нужно использовать оператор `throw`. В Java можно генерировать исключения объектов классов, которые являются подклассами класса `Throwable`. Классы `Throwable` имеют два основных подкласса: `Error` и `Exception`. Классы `Error` представляют серьезные проблемы, обычно связанные с состоянием виртуальной машины Java или среды выполнения, например, `OutOfMemoryError` или `StackOverflowError`. Классы `Exception` используются для представления ошибок, которые можно обработать программой.

Да, в Java можно генерировать два исключения одновременно, но это необходимо делать с осторожностью. Обычно исключение генерируется при возникновении определенной ошибки или проблемы в программе, и когда оно выбрасывается, выполнение текущего метода прерывается, и JVM ищет подходящий обработчик этого исключения. Если несколько исключений выброшены одновременно, то первое выброшенное исключение будет обработано, а остальные будут игнорированы.

Чтобы выбросить два или более исключения одновременно, можно использовать блок `try-catch` для каждого исключения или обернуть их в другое общее исключение и выбросить его. Однако, в большинстве случаев, хорошей практикой является выброс только одного исключения, которое наилучшим образом отображает проблему или ошибку, произошедшую в программе.

[к оглавлению](#исключения-и-ошибки)

## Объяснить, как работают операторы throw и throws. В чем их отличия?
Оператор `throw` используется для генерации исключения вручную в коде программы. Когда возникает ситуация, которая является ошибкой или неожиданным условием, программист может вызвать оператор `throw` и передать ему объект исключения. Это может быть любой объект, который является экземпляром класса, производного от класса `Throwable`. Например:

```java
public void someMethod(int value) throws SomeException {
    if (value < 0) {
        throw new SomeException("Value should be non-negative");
    }
    // код метода...
}
```

Оператор `throws`, используемый в сигнатуре метода, указывает, что этот метод может сгенерировать исключение, но не обрабатывает его внутри самого метода. Вместо этого, метод передает ответственность за обработку исключения вызывающему коду. Например:

```java
public void someMethod(int value) throws SomeException {
    if (value < 0) {
        throw new SomeException("Value should be non-negative");
    }
    // код метода...
}
```

Если вызывающий код не обрабатывает это исключение, оно будет передано дальше по стеку вызовов, пока не будет обработано в каком-либо обработчике исключений (`catch` блоке) или не вызовет аварийную остановку программы.

Таким образом, отличие между `throw` и `throws` заключается в том, что `throw` используется для фактического выбрасывания исключения, в то время как `throws` указывает на возможность выброса исключения из метода и переносит ответственность за его обработку вызывающему коду.

[к оглавлению](#исключения-и-ошибки)

## Объяснить правила реализации секции throws при переопределении метода и при описании конструкторов производного класса.
Правила реализации секции `throws` при переопределении метода и при описании конструкторов производного класса включают следующее:

1. При переопределении метода:
   - Если метод в базовом классе объявлен с использованием `throws` исключений, производный класс может:
      - Совсем не использовать секцию `throws`. В этом случае производный класс не может выбрасывать никаких проверяемых исключений, и он будет работать как если бы секции `throws` у него нет.
      - Использовать секцию `throws` со списком некоторых или всех исключений из секции базового класса. В этом случае производный класс может выбрасывать те же исключения, что и базовый метод, и также может выбрасывать другие исключения, которые не указаны в секции базового метода.
      - Использовать секцию `throws` с пустым списком исключений. В этом случае производный класс не выбрасывает никаких проверяемых исключений, в том числе тех, которые указаны в секции базового метода.

   Важно отметить, что производный класс не может выбрасывать проверяемые исключения, которые не указаны в секции базового метода, если он не использует секцию `throws`.

2. При описании конструкторов производного класса:
   - Если конструктор базового класса объявлен с использованием `throws` исключений, производный класс должен:
      - Явно вызывать конструктор базового класса с помощью `super()` в первой строке конструктора производного класса. При этом он также должен обработать или перенаправить исключения, указанные в секции `throws` конструктора базового класса.
      - Если производный класс имеет свои собственные исключения, которые могут быть выброшены в его конструкторе, он может также указать их в секции `throws` своего конструктора.

   Важно учесть, что при вызове конструктора базового класса в конструкторе производного класса, исключения, указанные в секции `throws` базового конструктора, должны быть перехвачены и обработаны или перенаправлены. Это означает, что производный конструктор также должен использовать секцию `throws`, в которой перечислены те же исключения, что и секция `throws` базового конструктора, плюс возможные исключения, выбрасываемые самим производным конструктором.
3. 
[к оглавлению](#исключения-и-ошибки)

## Как ведет себя блок throws при работе с проверяемыми и непроверяемыми исключениями?
Блок `throws` в Java используется для указания списка проверяемых исключений, которые может выбрасывать метод. Проверяемые исключения – это исключения, которые наследуются от класса `Exception` (и его подклассов), за исключением классов `RuntimeException` и его подклассов.

Поведение блока `throws` связано с обработкой и перехватом исключений в методах:

1. Если метод объявляет в секции `throws` проверяемые исключения, то вызывающий код должен либо сам обработать эти исключения с помощью блока `try-catch`, либо передать исключения дальше, используя также блок `throws`. В противном случае, компилятор выдаст ошибку.

2. Если метод выбрасывает непроверяемые исключения, то нет необходимости объявлять их в секции `throws`. Непроверяемые исключения – это исключения, которые наследуются от класса `RuntimeException` (и его подклассов). Компилятор не требует от вызывающего кода обрабатывать или объявлять эти исключения в секции `throws`.

3. Методы с пустым списком `throws` (т.е. методы, которые не выбрасывают исключения) или методы, которые выбрасывают только непроверяемые исключения, могут вызываться без использования блока `try-catch` или объявления `throws`. Однако, при вызове методов, выбрасывающих проверяемые исключения, их необходимо обрабатывать.

Обработка и перехват исключений через блоки `try-catch` позволяет программе управлять и корректно реагировать на возможные ошибочные ситуации, которые могут возникнуть во время выполнения кода.

[к оглавлению](#исключения-и-ошибки)

## Каков будет результат создания объекта, если конструктор при работе сгенерирует исключительную ситуацию?
Если конструктор генерирует исключение, создание объекта не будет завершено, и ссылка на объект не будет создана. Вместо этого, исключение будет передано обратно в вызывающий код. Это означает, что если конструктор выбрасывает проверяемое исключение, то код, вызывающий конструктор, должен либо обработать это исключение с помощью блока `try-catch`, либо передать его дальше с помощью блока `throws`.

Пример:

```java
public class Example {
    public Example() throws FileNotFoundException {
        // Возможно, какой-то код, который может вызвать FileNotFoundException
        throw new FileNotFoundException("Файл не найден");
    }

    public static void main(String[] args) {
        try {
            Example example = new Example(); // Вызывает конструктор, который генерирует исключение
            // Код дальше не выполнится, так как исключение было сгенерировано в конструкторе
        } catch (FileNotFoundException e) {
            System.out.println("Ошибка: " + e.getMessage());
        }
    }
}
```

В данном примере, при попытке создания объекта `Example`, конструктор выбрасывает исключение `FileNotFoundException`. Это исключение перехватывается в блоке `catch` в методе `main`, и выводится сообщение об ошибке. Обратите внимание, что код после создания объекта `Example` не выполнится из-за выброшенного исключения.

[к оглавлению](#исключения-и-ошибки)

## Нужно ли генерировать исключения, входящие в Java SE? Как создать собственные классы исключений?
Входящие в Java SE исключения, такие как `NullPointerException`, `IllegalArgumentException`, `FileNotFoundException`, и другие, обычно генерируются автоматически при возникновении соответствующих ситуаций во время выполнения программы. Эти исключения не требуется генерировать вручную, и они уже предоставлены в стандартной библиотеке Java для использования.

Однако, иногда может потребоваться создать собственные классы исключений, чтобы обрабатывать специфические исключительные ситуации, которые не покрываются стандартными исключениями. Создание собственных классов исключений позволяет более точно определить исключительные ситуации и предоставить более подробную информацию о возникшей ошибке.

Для создания собственного класса исключения нужно определить новый класс, который будет наследоваться от одного из классов исключений в Java. Часто используется наследование от класса `Exception` или его подклассов, если требуется определить проверяемое исключение, или от класса `RuntimeException` или его подклассов, если требуется определить непроверяемое исключение.

Пример создания собственного класса исключения:

```java
public class MyCustomException extends Exception {
    public MyCustomException() {
        super("Это мое собственное исключение");
    }

    public MyCustomException(String message) {
        super(message);
    }
}
```

В данном примере, мы создали новый класс `MyCustomException`, который наследуется от класса `Exception`. Этот класс предоставляет два конструктора - один без параметров, который устанавливает сообщение по умолчанию, и один с параметром `message`, который позволяет задать пользовательское сообщение об ошибке.

После создания собственного класса исключения, его можно использовать так же, как и стандартные исключения, с помощью оператора `throw`. Например:

```java
public class Example {
    public static void main(String[] args) {
        try {
            throw new MyCustomException("Моя ошибка");
        } catch (MyCustomException e) {
            System.out.println("Ошибка: " + e.getMessage());
        }
    }
}
```

В данном примере, при выполнении кода, будет сгенерировано собственное исключение `MyCustomException`, которое будет перехвачено в блоке `catch`, и выводится сообщение об ошибке.

[к оглавлению](#исключения-и-ошибки)
